<?xml version="1.0"?>
<robot xmlns:xacro="http://www.ros.org/wiki/xacro" >

    <xacro:include filename="inertial_macros.xacro"/>

    <material name="white">
        <color rgba="1 1 1 1" />
    </material>

    <material name="orange">
        <color rgba="1 0.3 0.1 1"/>
    </material>

    <material name="blue">
        <color rgba="0.2 0.2 1 1"/>
    </material>

    <material name="black">
        <color rgba="0 0 0 1"/>
    </material>

    <material name="red">
        <color rgba="1 0 0 1"/>
    </material>

    <!-- BASE LINK -->

    <link name="base_link">

    </link>

     <!-- BASE_FOOTPRINT LINK -->

    <joint name="base_footprint_joint" type="fixed">
        <parent link="base_link"/>
        <child link="base_footprint"/>
        <origin xyz="0 0 0" rpy="0 0 0"/>
    </joint>

    <link name="base_footprint">
    </link>

    
    <!-- CHASSIS LINK -->

    <joint name="chassis_joint" type="fixed">
        <parent link="base_link"/>
        <child link="chassis"/>
        <origin xyz="-0.1 0 0"/>
    </joint>

    <link name="chassis">
        <visual>
            <origin xyz="0.15 0 0.075"/>
            <geometry>
                <box size="0.3 0.3 0.15"/>
            </geometry>
            <material name="white"/>
        </visual>
        <collision>
            <origin xyz="0.15 0 0.075"/>
            <geometry>
                <box size="0.3 0.3 0.15"/>
            </geometry>
        </collision>
        <xacro:inertial_box mass="10" x="0.3" y="0.3" z="0.15">
            <origin xyz="0.15 0 0.075" rpy="0 0 0"/>
        </xacro:inertial_box>
    </link>

    <gazebo reference="chassis">
        <material>Gazebo/White</material>
    </gazebo>

    <!-- LEFT WHEEL LINK -->

    <joint name="left_wheel_joint" type="continuous">
        <parent link="base_link"/>
        <child link="left_wheel"/>
        <origin xyz="0 0.175 0" rpy="-${pi/2} 0 0" />
        <axis xyz="0 0 1"/>
    </joint>

    <link name="left_wheel">
        <visual>
            <geometry>
                <cylinder radius="0.05" length="0.04"/>
            </geometry>
            <material name="blue"/>
        </visual>
        <collision>
            <geometry>
                <cylinder radius="0.05" length="0.04"/>
            </geometry>
        </collision>
        <xacro:inertial_cylinder mass="0.1" length="0.04" radius="0.05">
            <origin xyz="0 0 0" rpy="0 0 0"/>
        </xacro:inertial_cylinder>
    </link>

    <gazebo reference="left_wheel">
        <material>Gazebo/Blue</material>
    </gazebo>




    <!-- RIGHT WHEEL LINK -->

    <joint name="right_wheel_joint" type="continuous">
        <parent link="base_link"/>
        <child link="right_wheel"/>
        <origin xyz="0 -0.175 0" rpy="${pi/2} 0 0" />
        <axis xyz="0 0 -1"/>
    </joint>

    <link name="right_wheel">
        <visual>
            <geometry>
                <cylinder radius="0.05" length="0.04"/>
            </geometry>
            <material name="blue"/>
        </visual>
        <collision>
            <geometry>
                <cylinder radius="0.05" length="0.04"/>
            </geometry>
        </collision>
        <xacro:inertial_cylinder mass="0.1" length="0.04" radius="0.05">
            <origin xyz="0 0 0" rpy="0 0 0"/>
        </xacro:inertial_cylinder>
    </link>

    <gazebo reference="right_wheel">
        <material>Gazebo/Blue</material>
    </gazebo>


    <!-- CASTER WHEEL LINK -->

    <joint name="caster_wheel_joint" type="fixed">
        <parent link="chassis"/>
        <child link="caster_wheel"/>
        <origin xyz="0.24 0 -0.01"/>
    </joint>


    <link name="caster_wheel">
        <visual>
            <geometry>
                <sphere radius="0.05"/>
            </geometry>
            <material name="black"/>
        </visual>
        <collision>
            <geometry>
                <sphere radius="0.05"/>
            </geometry>
        </collision>
        <xacro:inertial_sphere mass="2" radius="0.05">
            <origin xyz="0 0 0" rpy="0 0 0"/>
        </xacro:inertial_sphere>
    </link>

    <gazebo reference="caster_wheel">
        <material>Gazebo/Black</material>
        <mu1 value="0.001"/>
        <mu2 value="0.001"/>
    </gazebo>


    <link name="actuator_main_link">
        <inertial>
            <mass value="0.0002"/>
            <origin xyz="0 0 0"/>
            <inertia ixx="0.2" iyy="0.2" izz="0.2" ixy="0" ixz="0" iyz="0"/>
        </inertial>
    </link>
    

    <!-- Prismatic Joint (Moves the Actuator as One Unit) -->
    <joint name="linear_actuator" type="prismatic">
        <parent link="base_link"/>
        <child link="actuator_main_link"/>
        <origin xyz="0.37 0 -0.01" rpy="0 ${-0.1} 0"/>
        <axis xyz="0 0 1"/>  <!-- Moves in X-direction -->
        <limit lower="0" upper="0.2" effort="10.0" velocity="0.5"/>
    </joint>

    <!-- Actuator Link 1 (Fixed to Main Actuator) -->
    <link name="actuator_link">
        <inertial>
            <mass value="0.0001"/>
            <origin xyz="0 0 0"/>
            <inertia ixx="0.1" iyy="0.1" izz="0.1" ixy="0" ixz="0" iyz="0"/>
        </inertial>
        <visual>
            <geometry>
                <box size="0.5 0.08 0.01"/>
            </geometry>
        </visual>
        <collision>
            <geometry>
                <box size="0.5 0.08 0.01"/>
            </geometry>
        </collision>
        <xacro:inertial_box mass="0.0001" x="0.5" y="0.08" z="0.01">
            <origin xyz="0 0 0" rpy="0 0 0"/>
        </xacro:inertial_box>
    </link>
    

    <joint name="fixed_actuator1" type="fixed">
        <parent link="actuator_main_link"/>
        <child link="actuator_link"/>
        <origin xyz="0 0.075 0"/>
    </joint>
    <gazebo reference="fixed_actuator1">
        <material>Gazebo/Blue</material>
    </gazebo>

    <!-- Actuator Link 2 (Fixed to Main Actuator) -->
    <link name="actuator_link2">
        <inertial>
            <mass value="0.0001"/>
            <origin xyz="0 0 0"/>
            <inertia ixx="0.1" iyy="0.1" izz="0.1" ixy="0" ixz="0" iyz="0"/>
        </inertial>
        <visual>
            <geometry>
                <box size="0.5 0.08 0.01"/>
            </geometry>
        </visual>
        <collision>
            <geometry>
                <box size="0.5 0.08 0.01"/>
            </geometry>
        </collision>
        <xacro:inertial_box mass="0.0001" x="0.5" y="0.08" z="0.01">
            <origin xyz="0 0 0" rpy="0 0 0"/>
        </xacro:inertial_box>
    </link>

    <joint name="fixed_actuator2" type="fixed">
        <parent link="actuator_main_link"/>
        <child link="actuator_link2"/>
        <origin xyz="0 -0.075 0"/>
    </joint>
    <gazebo reference="fixed_actuator2">
        <material>Gazebo/Blue</material>
    </gazebo> 

    <ros2_control name="GazeboSystem" type="system">
    <hardware>
        <plugin>gazebo_ros2_control/GazeboSystem</plugin>
    </hardware>
    <joint name="linear_actuator">
        <command_interface name="position">
            <param name='min'>0</param>
            <param name='max'>0.5</param>
        </command_interface>
        <state_interface name="position">
            <param name="initial_value">0</param>
        </state_interface>
        <state_interface name="velocity"/>
        <state_interface name="effort"/>
    </joint>
    </ros2_control>
    <gazebo>
        <plugin filename="libgazebo_ros2_control.so" name="gazebo_ros2_control">
            <parameters>$(find articubot_one)/config/control_arm.yaml</parameters>
        </plugin>
    </gazebo>
</robot>